Workbook

Sheet 3 Demonstrações
B1: Empresa: | F1: First Year | G1: 2025 | I1: Unidade | J1: R$
A3: X | B3: Premissas | D3: =$G$1 -> 2025 | E3: =D3+1 -> 2026 | F3: =E3+1 -> 2027 | G3: =F3+1 -> 2028 | H3: =G3+1 -> 2029 | I3: =H3+1 -> 2030 | J3: =I3+1 -> 2031 | K3: =J3+1 -> 2032 | L3: =K3+1 -> 2033 | ... R3: =Q3+1 -> 2039
B5: Crescimento da Receita (Var %) | E5: -1
B6: Impostos (% Simples nacional) | D6: =Precificação!$C$26 -> 0.078
B7: Devoluções (% Faturamento) | D7: 0.01
B8: CPV (% Faturamento) | D8: =-Precificação!$D$5/Precificação!$D$2 -> 0.46752446
B9: SG&A (% Faturamento) | D9: =-Precificação!$D$6/Precificação!$D$2 -> 0.35604893
B10: D&A (% Imob. e Intang.) | D10: =Precificação!C25 -> 0
B11: Juros (% Dívida)
B12: Juros Revolver (% Dívida)
B13: Prazo Médio de Recebimento (Dias)
B14: Prazo Médio de Estoque (Dias)
B15: Prazo Médio de Pagamentos (Dias)
B16: Outras Receitas (Despesas) Operacionais (% Faturamento)
B17: Capex (R$)
B18: Captação Empréstimos (Pagamentos) (R$)
B19: Vendas (Unidades de 250g/Ano) | D19: =Precificação!B5*12 -> 8640
B20: Preço da Unidade (R$/Unidades de 250g) | D20: =Precificação!B34 -> 46.859699
B21: Sacas Compradas (Sacas/Ano) | D21: ='Investimento Inicial'!C5 -> 45
B22: Preço da Saca (R$) | D22: =Precificação!B4*60 -> 3100 | E22: =D22 -> 3100 | F22: =E22 -> 3100 | G22: =F22 -> 3100 | H22: =G22 -> 3100 | I22: =H22 -> 3100 | J22: =I22 -> 3100 | K22: =J22 -> 3100 | L22: =K22 -> 3100 | ... R22: =Q22 -> 3100
A24: X | B24: DRE | D24: =$G$1 -> 2025 | E24: =D24+1 -> 2026 | F24: =E24+1 -> 2027 | G24: =F24+1 -> 2028 | H24: =G24+1 -> 2029 | I24: =H24+1 -> 2030 | J24: =I24+1 -> 2031 | K24: =J24+1 -> 2032 | L24: =K24+1 -> 2033 | ... R24: =Q24+1 -> 2039
B26: Receita Operacional Bruta | D26: =D19*D20 -> 404867.8 | E26: =E19*E20 -> 0 | F26: =F19*F20 -> 0 | G26: =G19*G20 -> 0 | H26: =H19*H20 -> 0 | I26: =I19*I20 -> 0 | J26: =J19*J20 -> 0 | K26: =K19*K20 -> 0 | ... R26: =R19*R20 -> 0
B27: Deduções Das Receitas | D27: =D28+D29 -> 35628.367 | E27: =E28+E29 -> 0 | F27: =F28+F29 -> 0 | G27: =G28+G29 -> 0 | H27: =H28+H29 -> 0 | I27: =I28+I29 -> 0 | J27: =J28+J29 -> 0 | K27: =K28+K29 -> 0 | ... R27: =R28+R29 -> 0
B28: Impostos sobre vendas | D28: =D6*D26 -> 31579.689 | I28: =H28*(1+I6) -> 0 | J28: =I28*(1+J6) -> 0 | K28: =J28*(1+K6) -> 0 | L28: =K28*(1+L6) -> 0 | M28: =L28*(1+M6) -> 0 | N28: =M28*(1+N6) -> 0 | O28: =N28*(1+O6) -> 0 | P28: =O28*(1+P6) -> 0 | ... R28: =Q28*(1+R6) -> 0
B29: Devoluções | D29: =$D$7*$D$26 -> 4048.678
B30: Receita Operacional Líquida | D30: =D26-D27 -> 369239.44 | E30: =E26-E27 -> 0 | F30: =F26-F27 -> 0 | G30: =G26-G27 -> 0 | H30: =H26-H27 -> 0 | I30: =I26-I27 -> 0 | J30: =J26-J27 -> 0 | K30: =K26-K27 -> 0 | ... R30: =R26-R27 -> 0
B31: Custo dos Produtos Vendidos | D31: =$D$8*D26 -> 189285.6 | I31: =H31*(1+I8) -> 0 | J31: =I31*(1+J8) -> 0 | K31: =J31*(1+K8) -> 0 | L31: =K31*(1+L8) -> 0 | M31: =L31*(1+M8) -> 0 | N31: =M31*(1+N8) -> 0 | O31: =N31*(1+O8) -> 0 | P31: =O31*(1+P8) -> 0 | ... R31: =Q31*(1+R8) -> 0
B32: Lucro Operacional Bruto | D32: =D30-D31 -> 179953.84 | E32: =E30-E31 -> 0 | F32: =F30-F31 -> 0 | G32: =G30-G31 -> 0 | H32: =H30-H31 -> 0 | I32: =I30-I31 -> 0 | J32: =J30-J31 -> 0 | K32: =K30-K31 -> 0 | ... R32: =R30-R31 -> 0
B33: SG&A | D33: =$D$9*$D$26 -> 144152.75 | I33: =H33+(1*I9) -> 0 | J33: =I33+(1*J9) -> 0 | K33: =J33+(1*K9) -> 0 | L33: =K33+(1*L9) -> 0 | M33: =L33+(1*M9) -> 0 | N33: =M33+(1*N9) -> 0 | O33: =N33+(1*O9) -> 0 | P33: =O33+(1*P9) -> 0 | ... R33: =Q33+(1*R9) -> 0
B34: Resultado Operacional | D34: =D32-D33 -> 35801.09 | E34: =E32-E33 -> 0 | F34: =F32-F33 -> 0 | G34: =G32-G33 -> 0 | H34: =H32-H33 -> 0 | I34: =I32-I33 -> 0 | J34: =J32-J33 -> 0 | K34: =K32-K33 -> 0 | ... R34: =R32-R33 -> 0
B35: Outros Resultados | D35: 0 | I35: =H35 -> 0 | J35: =I35 -> 0 | K35: =J35 -> 0 | L35: =K35 -> 0 | M35: =L35 -> 0 | N35: =M35 -> 0 | O35: =N35 -> 0 | P35: =O35 -> 0 | ... R35: =Q35 -> 0
B36: Lucro Antes do Resultado Financeiro (EBIT) | D36: =D34+D35 -> 35801.09 | E36: =E34+E35 -> 0 | F36: =F34+F35 -> 0 | G36: =G34+G35 -> 0 | H36: =H34+H35 -> 0 | I36: =I34+I35 -> 0 | J36: =J34+J35 -> 0 | K36: =K34+K35 -> 0 | ... R36: =R34+R35 -> 0
B37: Receita Financeira Líquida | D37: =D38-D39 -> -12938.099 | E37: =E38-E39 -> 0 | F37: =F38-F39 -> 0 | G37: =G38-G39 -> 0 | H37: =H38-H39 -> 0 | I37: =I38-I39 -> 0 | J37: =J38-J39 -> 0 | K37: =K38-K39 -> 0 | ... R37: =R38-R39 -> 0
B38: Receita Financeira | I38: =H38*(1+I108) -> 0 | J38: =I38*(1+J108) -> 0 | K38: =J38*(1+K108) -> 0 | L38: =K38*(1+L108) -> 0 | M38: =L38*(1+M108) -> 0 | N38: =M38*(1+N108) -> 0 | O38: =N38*(1+O108) -> 0 | P38: =O38*(1+P108) -> 0 | ... R38: =Q38*(1+R108) -> 0
B39: Despesas Financeira | D39: ='Simulação Empréstimo'!K6 -> 12938.099 | I39: =I135 -> 0 | J39: =J135 -> 0 | K39: =K135 -> 0 | L39: =L135 -> 0 | M39: =M135 -> 0 | N39: =N135 -> 0 | O39: =O135 -> 0 | P39: =P135 -> 0 | ... R39: =R135 -> 0
B40: Lucro Antes dos Impostos (EBT) | D40: =D36+D37 -> 22862.991 | E40: =E36+E37 -> 0 | F40: =F36+F37 -> 0 | G40: =G36+G37 -> 0 | H40: =H36+H37 -> 0 | I40: =I36+I37 -> 0 | J40: =J36+J37 -> 0 | K40: =K36+K37 -> 0 | ... R40: =R36+R37 -> 0
B41: Tributos (Não se Aplica no Simples) | D41: =D42+D43 -> 0 | E41: =E42+E43 -> 0 | F41: =F42+F43 -> 0 | G41: =G42+G43 -> 0 | H41: =H42+H43 -> 0 | I41: =I42+I43 -> 0 | J41: =J42+J43 -> 0 | K41: =K42+K43 -> 0 | ... R41: =R42+R43 -> 0
B42: Imposto de Renda Pessoa Jurídica - IRPJ | I42: 0 | J42: 0 | K42: 0 | L42: 0 | M42: 0 | N42: 0 | O42: 0 | P42: 0 | Q42: 0 | R42: 0
B43: Contribuição Social s/Lucro Líquido - CSLL | I43: 0 | J43: 0 | K43: 0 | L43: 0 | M43: 0 | N43: 0 | O43: 0 | P43: 0 | Q43: 0 | R43: 0
B44: Lucro Líquido Do Exercício | D44: =D40-D41 -> 22862.991 | E44: =E40-E41 -> 0 | F44: =F40-F41 -> 0 | G44: =G40-G41 -> 0 | H44: =H40-H41 -> 0 | I44: =I40-I41 -> 0 | J44: =J40-J41 -> 0 | K44: =K40-K41 -> 0 | ... R44: =R40-R41 -> 0
...

Sheet Fontes
B2: IPCA | C2: https://www.bcb.gov.br/content/focus/focus/R20241227.pdf
B3: CDI | C3: https://www.bcb.gov.br/content/focus/focus/R20241227.pdf
B5: Sacas/ano
B30: Preço da Saca | C30: https://www.noticiasagricolas.com.br/cotacoes/cafe
B31: Prêmio Café Especial | C31: Conversa com Torrador
B32: Alíquota Simples Nacional (Anexo 2) | C32: https://www.contabilizei.com.br/contabilidade-online/tabela-simples-nacional-completa/
B33: Exemplo de Empresa | C33: https://www.3coracoes.com.br/wp-content/uploads/2024/08/Demonstracoes-Financeira-2023-Tres-Coracoes-Alimentos-SA-BR-GAAP.pdf?x20808
B34: Energia (R$/kWh) Grupo A4 - Modalidade Tarifária Verde | C34: https://www.dme-pc.com.br/atendimento/tarifas
B35: Consumo de Energia
B36: Preço GLP | C36: https://precos.petrobras.com.br/sele%C3%A7%C3%A3o-de-estados-glp
B37: Consumo GLP | C37: https://kaffeetorradores.com/product/torrador-basico-15kg/
B38: Preço Água
B39: Consumo Água

Sheet Simulação Empréstimo
C1: =YEAR(TODAY()) -> 2026 | D1: =C1+1 -> 2027 | E1: =D1+1 -> 2028 | F1: =E1+1 -> 2029 | G1: =F1+1 -> 2030 | H1: =G1+1 -> 2031
B2: IPCA | C2: 0.039 | D2: 0.0378 | E2: 0.036 | F2: 0.035 | G2: 0.035 | H2: 0.035
B3: CDI | C3: 0.1475 | D3: 0.125 | E3: 0.105 | F3: 0.1 | G3: 0.1 | H3: 0.1
B5: Volume | C5: 250000 | E5: Custos Mensais | J5: Ano | K5: Juros | L5: Amortização | M5: Saldo Devedor
B6: Indexador | C6: CDI+ | E6: Custos Anuais | J6: 2025 | K6: 12938.099 | L6: 0 | M6: 250000
B7: ="Taxa "&" ("&C6&")" -> Taxa (CDI+) | C7: 0.07 | J7: 2026 | K7: 44124.906 | L7: 41666.667 | M7: 208333.33
B8: Prazo | C8: 60 | E8: Custos Flat | J8: 2027 | K8: 30846.301 | L8: 55555.556 | M8: 152777.78
B9: Carência Amort. | C9: 6 | E9: Fundo de Despesa | J9: 2028 | K9: 20889.875 | L9: 55555.556 | M9: 97222.222
B10: Data estimada emissão | C10: 45901 | E10: Trigger | F10: 0 | J10: 2029 | K10: 11774.293 | L10: 55555.556 | M10: 41666.667
B11: Amortização | C11: Mensal | D11: 1 | E11: Fundo de Reserva | J11: 2030 | K11: 2848.6193 | L11: 41666.667 | M11: -1.891749e-10
B12: Tipo Amortização | C12: SAC | E12: Volume Líquido | F12: =C5-F11-F9-F8 -> 250000
B14: # | C14: DATA | D14: ANO | E14: AMORTIZAÇÃO | F14: TAXA EFETIVA | G14: JUROS | H14: PARCELA | I14: SALDO DEVEDOR
B15: 0 | C15: 45901 | D15: =YEAR(C15) -> 2025 | E15: 0 | F15: 0 | I15: =$C$5 -> 250000
B16: 1 | C16: 45931 | D16: =YEAR(C16) -> 2025 | E16: 0 | F16: 0.017250798 | G16: 4312.6996 | H16: 4312.6996 | I16: 250000
B17: 2 | C17: 45962 | D17: =YEAR(C17) -> 2025 | E17: 0 | F17: 0.017250798 | G17: 4312.6996 | H17: 4312.6996 | I17: 250000
B18: 3 | C18: 45992 | D18: =YEAR(C18) -> 2025 | E18: 0 | F18: 0.017250798 | G18: 4312.6996 | H18: 4312.6996 | I18: 250000
B19: 4 | C19: 46023 | D19: =YEAR(C19) -> 2026 | E19: 0 | F19: 0.015573496 | G19: 3893.374 | H19: 3893.374 | I19: 250000
B20: 5 | C20: 46054 | D20: =YEAR(C20) -> 2026 | E20: 0 | F20: 0.015573496 | G20: 3893.374 | H20: 3893.374 | I20: 250000
B21: 6 | C21: 46082 | D21: =YEAR(C21) -> 2026 | E21: 0 | F21: 0.015573496 | G21: 3893.374 | H21: 3893.374 | I21: 250000
B22: 7 | C22: 46113 | D22: =YEAR(C22) -> 2026 | E22: 4629.6296 | F22: 0.015573496 | G22: 3893.374 | H22: 8523.0036 | I22: 245370.37
B23: 8 | C23: 46143 | D23: =YEAR(C23) -> 2026 | E23: 4629.6296 | F23: 0.015573496 | G23: 3821.2745 | H23: 8450.9041 | I23: 240740.74
B24: 9 | C24: 46174 | D24: =YEAR(C24) -> 2026 | E24: 4629.6296 | F24: 0.015573496 | G24: 3749.175 | H24: 8378.8046 | I24: 236111.11
B25: 10 | C25: 46204 | D25: =YEAR(C25) -> 2026 | E25: 4629.6296 | F25: 0.015573496 | G25: 3677.0755 | H25: 8306.7051 | I25: 231481.48
B26: 11 | C26: 46235 | D26: =YEAR(C26) -> 2026 | E26: 4629.6296 | F26: 0.015573496 | G26: 3604.9759 | H26: 8234.6056 | I26: 226851.85
B27: 12 | C27: 46266 | D27: =YEAR(C27) -> 2026 | E27: 4629.6296 | F27: 0.015573496 | G27: 3532.8764 | H27: 8162.5061 | I27: 222222.22
... B75: 60 | C75: 47727 | D75: =YEAR(C75) -> 2030 | E75: 4629.6296 | F75: 0.013673373 | G75: 63.302652 | H75: 4692.9323 | I75: -1.891749e-10

Sheet Investimento Inicial
A2: Máquina de torra seminova | B2: 70000
A3: Balança de comércio | B3: 500
A4: 6 meses de aluguel | B4: =$C$4*6 -> 30000 | C4: =-Precificação!$B$10 -> 5000
A5: 12 meses de café | B5: =$C$5*$D$5 -> 139500 | C5: =SUM('Fluxo de Caixa'!$C$4:$AZ$4) -> 45 | D5: 3100
A6: Seguro | B6: 5000
A7: Marketing | B7: 3000
A8: Identidade visual | B8: 4000
A9: Site | B9: 3000
A10: 6 meses de contabilidade | B10: =$C$10*6 -> 6000 | C10: 1000
A11: Total | B11: =SUM(B2:B10) -> 261000

Sheet Precificação
A2: Produção mensal (kg) | B2: 180 | C2: Faturamento | D2: =$B$5*B34 -> 33738.984
A3: Data | B3: 45840 | C3: Lucro | D3: =$D$2+B32 -> 1606.6183
A4: Preço café verde (R$/kg) | B4: =3100/60 -> 51.666667 | C4: Margem | D4: =$D$3/$D$2 -> 0.047619048
A5: Pacotinhos | B5: =$B$2/$B$6 -> 720 | C5: CPV | D5: =($B$12-$B$10)+$B$17+$B$22 -> -15773.8
A6: Peso do Pacotinho | B6: 0.25 | C6: SG&A | D6: =$B$10+$B$24+$B$27+$B$28+$B$29 -> -12012.729
B8: Torrefação | E8: %
A9: Frete do café verde | B9: =-1000 -> -1000 | E9: =-B9/$B$32 -> -0.031121269
A10: Aluguel do galpão | B10: -5000 | E10: =-B10/$B$32 -> -0.15560635
A11: Custo café verde | B11: =-$B$4*$B$2 -> -9300 | E11: =-B11/$B$32 -> -0.28942781
A12: Custos na torrefação | B12: =SUM(B9:B11) -> -15300 | E12: =-B12/$B$32 -> -0.47615542
A14: Perda de peso na torra | B14: =-$C$14*$B$4*$B$2 -> -1674 | C14: 0.18 | E14: =-B14/$B$32 -> -0.052097005
A15: Água e luz | B15: =-300 -> -300 | E15: =-B15/$B$32 -> -0.0093363808
A16: GLP | B16: =-$C$16*$B$2 -> -154.8 | C16: 0.86 | E16: =-B16/$B$32 -> -0.0048175725
A17: Custos de torra | B17: =SUM(B14:B16) -> -2128.8 | E17: =-B17/$B$32 -> -0.066250958
A19: Pacotes | B19: =-$C$19*$D$19 -> -2880 | C19: =$B$5 -> 720 | D19: 4 | E19: =-B19/$B$32 -> -0.089629256
A20: Trabalho direto | B20: 0 | C20: Inclui INSS e FGTS | D20: 0.3 | E20: =-B20/$B$32 -> 0
A21: Outros materiais | B21: =-$C$21*($B$2*$B$4) -> -465 | C21: 0.05 | E21: =-B21/$B$32 -> -0.01447139
A22: Custos materiais | B22: =SUM(B19:B21) -> -3345 | E22: =-B22/$B$32 -> -0.10410065
A24: Outros Custos | B24: =-$C$24*$B$2*$B$4 -> -465 | C24: 0.05 | E24: =-B24/$B$32 -> -0.01447139
A25: Juros | B25: =-AVERAGE('Simulação Empréstimo'!$K$6:$K$11)/12 -> -1714.1957 | E25: =-B25/$B$32 -> -0.053347947
A26: Impostos Simples | B26: =-$C$26*$D$2 -> -2631.6407 | C26: 0.078 | D26: Tabela II Simples | E26: =-B26/$B$32 -> -0.0819
A27: Perdas operacionais | B27: =-$C$27*($B$2*$B$4) -> -186 | C27: 0.02 | E27: =-B27/$B$32 -> -0.0057885561
A28: Pró-labore | B28: =-$D$2*$C$28 -> -2361.7288 | C28: 0.07 | E28: =-B28/$B$32 -> -0.0735
A29: Marketing e Contabilidade | B29: -4000
A30: Outros custos | B30: =SUM(B24:B29) -> -11358.565 | E30: =-B30/$B$32 -> -0.35349297
A32: Custos totais | B32: =SUM($B$30+$B$22+$B$17+$B$12) -> -32132.365
A34: Preço por pacotinho | B34: =(-B32+(-$B$32*$C$34))/$B$5 -> 46.859699 | C34: 0.05

Sheet Fluxo de Caixa
A1: Preço Saca de Café | C1: 0 | G1: =C$1+1 -> 1 | K1: =G$1+1 -> 2 | O1: =K$1+1 -> 3 | S1: =O$1+1 -> 4 | W1: =S$1+1 -> 5 | AA1: =W$1+1 -> 6 | AE1: =AA$1+1 -> 7 | AI1: =AE$1+1 -> 8 | AM1: =AI$1+1 -> 9 | AQ1: =AM$1+1 -> 10 | AU1: =AQ$1+1 -> 11 | AY1: =AU$1+1 -> 12 | BC1: =AY$1+1 -> 13 | BG1: =BC$1+1 -> 14 | BK1: =BG$1+1 -> 15 | BO1: =BK$1+1 -> 16 | BS1: =BO$1+1 -> 17 | BW1: =BS$1+1 -> 18 | CA1: =BW$1+1 -> 19 | CE1: =CA$1+1 -> 20 | CI1: =CE$1+1 -> 21 | CM1: =CI$1+1 -> 22 | CQ1: =CM$1+1 -> 23 | CU1: =CQ$1+1 -> 24 | CY1: =CU$1+1 -> 25 | DC1: =CY$1+1 -> 26 | DG1: =DC$1+1 -> 27 | DK1: =DG$1+1 -> 28 | DO1: =DK$1+1 -> 29 | DS1: =DO$1+1 -> 30 | DW1: =DS$1+1 -> 31 | EA1: =DW$1+1 -> 32 | EE1: =EA$1+1 -> 33 | EI1: =EE$1+1 -> 34 | EM1: =EI$1+1 -> 35 | EQ1: =EM$1+1 -> 36 | EU1: =EQ$1+1 -> 37 | EY1: =EU$1+1 -> 38 | FC1: =EY$1+1 -> 39 | FG1: =FC$1+1 -> 40 | FK1: =FG$1+1 -> 41 | FO1: =FK$1+1 -> 42 | FS1: =FO$1+1 -> 43 | FW1: =FS$1+1 -> 44 | GA1: =FW$1+1 -> 45 | GE1: =GA$1+1 -> 46 | GI1: =GE$1+1 -> 47 | GM1: =GI$1+1 -> 48 | GQ1: =GM$1+1 -> 49 | GU1: =GQ$1+1 -> 50 | GY1: =GU$1+1 -> 51 | HC1: =GY$1+1 -> 52 | HG1: =HC$1+1 -> 53 | HK1: =HG$1+1 -> 54 | HO1: =HK$1+1 -> 55 | HS1: =HO$1+1 -> 56 | HW1: =HS$1+1 -> 57 | IA1: =HW$1+1 -> 58 | IE1: =IA$1+1 -> 59 | II1: =IE$1+1 -> 60 | IM1: =II$1+1 -> 61 | IQ1: =IM$1+1 -> 62 | IU1: =IQ$1+1 -> 63 | IY1: =IU$1+1 -> 64 | JC1: =IY$1+1 -> 65 | JG1: =JC$1+1 -> 66 | JK1: =JG$1+1 -> 67 | JO1: =JK$1+1 -> 68 | JS1: =JO$1+1 -> 69 | JW1: =JS$1+1 -> 70 | KA1: =JW$1+1 -> 71 | KE1: =KA$1+1 -> 72
A2: 3100 | C2: Receitas | D2: R$ | G2: Receitas | H2: R$ | K2: Receitas | L2: R$ | O2: Receitas | P2: R$ | S2: Receitas | T2: R$ | W2: Receitas | X2: R$ | AA2: Receitas | AB2: R$ | AE2: Receitas | AF2: R$ | AI2: Receitas | AJ2: R$ | AM2: Receitas | AN2: R$ | AQ2: Receitas | AR2: R$ | AU2: Receitas | AV2: R$ | AY2: Receitas | AZ2: R$ | BC2: Receitas | BD2: R$ | BG2: Receitas | BH2: R$ | BK2: Receitas | BL2: R$ | BO2: Receitas | BP2: R$ | BS2: Receitas | BT2: R$ | BW2: Receitas | BX2: R$ | CA2: Receitas | CB2: R$ | CE2: Receitas | CF2: R$ | CI2: Receitas | CJ2: R$ | CM2: Receitas | CN2: R$ | CQ2: Receitas | CR2: R$ | CU2: Receitas | CV2: R$ | CY2: Receitas | CZ2: R$ | DC2: Receitas | DD2: R$ | DG2: Receitas | DH2: R$ | DK2: Receitas | DL2: R$ | DO2: Receitas | DP2: R$ | DS2: Receitas | DT2: R$ | DW2: Receitas | DX2: R$ | EA2: Receitas | EB2: R$ | EE2: Receitas | EF2: R$ | EI2: Receitas | EJ2: R$ | EM2: Receitas | EN2: R$ | EQ2: Receitas | ER2: R$ | EU2: Receitas | EV2: R$ | EY2: Receitas | EZ2: R$ | FC2: Receitas | FD2: R$ | FG2: Receitas | FH2: R$ | FK2: Receitas | FL2: R$ | FO2: Receitas | FP2: R$ | FS2: Receitas | FT2: R$ | FW2: Receitas | FX2: R$ | GA2: Receitas | GB2: R$ | GE2: Receitas | GF2: R$ | GI2: Receitas | GJ2: R$ | GM2: Receitas | GN2: R$ | GQ2: Receitas | GR2: R$ | GU2: Receitas | GV2: R$ | GY2: Receitas | GZ2: R$ | HC2: Receitas | HD2: R$ | HG2: Receitas | HH2: R$ | HK2: Receitas | HL2: R$ | HO2: Receitas | HP2: R$ | HS2: Receitas | HT2: R$ | HW2: Receitas | HX2: R$ | IA2: Receitas | IB2: R$ | IE2: Receitas | IF2: R$ | II2: Receitas | IJ2: R$ | IM2: Receitas | IN2: R$ | IQ2: Receitas | IR2: R$ | IU2: Receitas | IV2: R$ | IY2: Receitas | IZ2: R$ | JC2: Receitas | JD2: R$ | JG2: Receitas | JH2: R$ | JK2: Receitas | JL2: R$ | JO2: Receitas | JP2: R$ | JS2: Receitas | JT2: R$ | JW2: Receitas | JX2: R$ | KA2: Receitas | KB2: R$ | KE2: Receitas | KF2: R$
A3: 40 | C3: Venda de café | D3: =((D$4*60)/0.25)*D$5 -> 28800 | E3: =-(D$3+D$30)/D$30 -> -0.78362458 | G3: Venda de café | H3: =((H$4*60)/0.25)*H$5 -> 28800 | I3: =-(H$3+H$30)/H$30 -> 0.32706689 | K3: Venda de café | L3: =((L$4*60)/0.25)*L$5 -> 28800 | M3: =-(L$3+L$30)/L$30 -> 0.32706689 | O3: Venda de café | P3: =((P$4*60)/0.25)*P$5 -> 28800 | Q3: =-(P$3+P$30)/P$30 -> -0.43085249 | S3: Venda de café | T3: =((T$4*60)/0.25)*T$5 -> 28800 | U3: =-(T$3+T$30)/T$30 -> 0.32706689 | W3: Venda de café | X3: =((X$4*60)/0.25)*X$5 -> 28800 | Y3: =-(X$3+X$30)/X$30 -> 0.32706689 | AA3: Venda de café | AB3: =((AB$4*60)/0.25)*AB$5 -> 28800 | AC3: =-(AB$3+AB$30)/AB$30 -> -0.50131939 | AE3: Venda de café | AF3: =((AF$4*60)/0.25)*AF$5 -> 38400 | AG3: =-(AF$3+AF$30)/AF$30 -> 0.44732005 | AI3: Venda de café | AJ3: =((AJ$4*60)/0.25)*AJ$5 -> 38400 | AK3: =-(AJ$3+AJ$30)/AJ$30 -> 0.44732005 | AM3: Venda de café | AN3: =((AN$4*60)/0.25)*AN$5 -> 38400 | AO3: =-(AN$3+AN$30)/AN$30 -> -0.40678303 | AQ3: Venda de café | AR3: =((AR$4*60)/0.25)*AR$5 -> 38400 | AS3: =-(AR$3+AR$30)/AR$30 -> 0.44732005 | AU3: Venda de café | AV3: =((AV$4*60)/0.25)*AV$5 -> 38400 | AW3: =-(AV$3+AV$30)/AV$30 -> 0.40265796 | AY3: Venda de café | AZ3: =((AZ$4*60)/0.25)*AZ$5 -> 38400 | BA3: =-(AZ$3+AZ$30)/AZ$30 -> -0.44085755 | BC3: Venda de café | BD3: =((BD$4*60)/0.25)*BD$5 -> 38400 | BE3: =-(BD$3+BD$30)/BD$30 -> 0.40265796 | BG3: Venda de café | BH3: =((BH$4*60)/0.25)*BH$5 -> 48000 | BI3: =-(BH$3+BH$30)/BH$30 -> 0.52539808 | BK3: Venda de café | BL3: =((BL$4*60)/0.25)*BL$5 -> 48000 | BM3: =-(BL$3+BL$30)/BL$30 -> -0.39215266 | BO3: Venda de café | BP3: =((BP$4*60)/0.25)*BP$5 -> 48000 | BQ3: =-(BP$3+BP$30)/BP$30 -> 0.52539808 | BS3: Venda de café | BT3: =((BT$4*60)/0.25)*BT$5 -> 48000 | BU3: =-(BT$3+BT$30)/BT$30 -> 0.52539808 | BW3: Venda de café | BX3: =((BX$4*60)/0.25)*BX$5 -> 48000 | BY3: =-(BX$3+BX$30)/BX$30 -> -0.41511344 | CA3: Venda de café | CB3: =((CB$4*60)/0.25)*CB$5 -> 48000 | CC3: =-(CB$3+CB$30)/CB$30 -> 0.52539808 | CE3: Venda de café | CF3: =((CF$4*60)/0.25)*CF$5 -> 57600 | CG3: =-(CF$3+CF$30)/CF$30 -> 0.61989794 | CI3: Venda de café | CJ3: =((CJ$4*60)/0.25)*CJ$5 -> 57600 | CK3: =-(CJ$3+CJ$30)/CJ$30 -> -0.37633852 | CM3: Venda de café | CN3: =((CN$4*60)/0.25)*CN$5 -> 57600 | CO3: =-(CN$3+CN$30)/CN$30 -> 0.61989794 | CQ3: Venda de café | CR3: =((CR$4*60)/0.25)*CR$5 -> 57600 | CS3: =-(CR$3+CR$30)/CR$30 -> 0.61989794 | CU3: Venda de café | CV3: =((CV$4*60)/0.25)*CV$5 -> 57600 | CW3: =-(CV$3+CV$30)/CV$30 -> -0.37633852 | CY3: Venda de café | CZ3: =((CZ$4*60)/0.25)*CZ$5 -> 57600 | DA3: =-(CZ$3+CZ$30)/CZ$30 -> 0.61989794 | DC3: Venda de café | DD3: =((DD$4*60)/0.25)*DD$5 -> 57600 | DE3: =-(DD$3+DD$30)/DD$30 -> 0.61989794 | DG3: Venda de café | DH3: =((DH$4*60)/0.25)*DH$5 -> 67200 | DI3: =-(DH$3+DH$30)/DH$30 -> -0.36452937 | DK3: Venda de café | DL3: =((DL$4*60)/0.25)*DL$5 -> 67200 | DM3: =-(DL$3+DL$30)/DL$30 -> 0.69489834 | DO3: Venda de café | DP3: =((DP$4*60)/0.25)*DP$5 -> 67200 | DQ3: =-(DP$3+DP$30)/DP$30 -> 0.69489834 | DS3: Venda de café | DT3: =((DT$4*60)/0.25)*DT$5 -> 67200 | DU3: =-(DT$3+DT$30)/DT$30 -> -0.36452937 | DW3: Venda de café | DX3: =((DX$4*60)/0.25)*DX$5 -> 67200 | DY3: =-(DX$3+DX$30)/DX$30 -> 0.66111332 | EA3: Venda de café | EB3: =((EB$4*60)/0.25)*EB$5 -> 67200 | EC3: =-(EB$3+EB$30)/EB$30 -> 0.66111332 | EE3: Venda de café | EF3: =((EF$4*60)/0.25)*EF$5 -> 67200 | EG3: =-(EF$3+EF$30)/EF$30 -> -0.40401648 | EI3: Venda de café | EJ3: =((EJ$4*60)/0.25)*EJ$5 -> 76800 | EK3: =-(EJ$3+EJ$30)/EJ$30 -> 0.71963671 | EM3: Venda de café | EN3: =((EN$4*60)/0.25)*EN$5 -> 76800 | EO3: =-(EN$3+EN$30)/EN$30 -> 0.71963671 | EQ3: Venda de café | ER3: =((ER$4*60)/0.25)*ER$5 -> 76800 | ES3: =-(ER$3+ER$30)/ER$30 -> -0.36032301 | EU3: Venda de café | EV3: =((EV$4*60)/0.25)*EV$5 -> 76800 | EW3: =-(EV$3+EV$30)/EV$30 -> 0.71963671 | EY3: Venda de café | EZ3: =((EZ$4*60)/0.25)*EZ$5 -> 76800 | FA3: =-(EZ$3+EZ$30)/EZ$30 -> 0.71963671 | FC3: Venda de café | FD3: =((FD$4*60)/0.25)*FD$5 -> 76800 | FE3: =-(FD$3+FD$30)/FD$30 -> -0.39173422 | FG3: Venda de café | FH3: =((FH$4*60)/0.25)*FH$5 -> 86400 | FI3: =-(FH$3+FH$30)/FH$30 -> 0.7680862 | FK3: Venda de café | FL3: =((FL$4*60)/0.25)*FL$5 -> 86400 | FM3: =-(FL$3+FL$30)/FL$30 -> 0.7680862 | FO3: Venda de café | FP3: =((FP$4*60)/0.25)*FP$5 -> 86400 | FQ3: =-(FP$3+FP$30)/FP$30 -> -0.35313071 | FS3: Venda de café | FT3: =((FT$4*60)/0.25)*FT$5 -> 86400 | FU3: =-(FT$3+FT$30)/FT$30 -> 0.7680862 | FW3: Venda de café | FX3: =((FX$4*60)/0.25)*FX$5 -> 86400 | FY3: =-(FX$3+FX$30)/FX$30 -> 0.7680862 | GA3: Venda de café | GB3: =((GB$4*60)/0.25)*GB$5 -> 86400 | GC3: =-(GB$3+GB$30)/GB$30 -> -0.36780362 | GE3: Venda de café | GF3: =((GF$4*60)/0.25)*GF$5 -> 86400 | GG3: =-(GF$3+GF$30)/GF$30 -> 0.7680862 | GI3: Venda de café | GJ3: =((GJ$4*60)/0.25)*GJ$5 -> 96000 | GK3: =-(GJ$3+GJ$30)/GJ$30 -> 0.80885676 | GM3: Venda de café | GN3: =((GN$4*60)/0.25)*GN$5 -> 96000 | GO3: =-(GN$3+GN$30)/GN$30 -> -0.34725935 | GQ3: Venda de café | GR3: =((GR$4*60)/0.25)*GR$5 -> 96000 | GS3: =-(GR$3+GR$30)/GR$30 -> 0.80885676 | GU3: Venda de café | GV3: =((GV$4*60)/0.25)*GV$5 -> 96000 | GW3: =-(GV$3+GV$30)/GV$30 -> 0.80885676 | GY3: Venda de café | GZ3: =((GZ$4*60)/0.25)*GZ$5 -> 96000 | HA3: =-(GZ$3+GZ$30)/GZ$30 -> -0.34725935 | HC3: Venda de café | HD3: =((HD$4*60)/0.25)*HD$5 -> 96000 | HE3: =-(HD$3+HD$30)/HD$30 -> 0.80885676 | HG3: Venda de café | HH3: =((HH$4*60)/0.25)*HH$5 -> 96000 | HI3: =-(HH$3+HH$30)/HH$30 -> 0.80885676 | HK3: Venda de café | HL3: =((HL$4*60)/0.25)*HL$5 -> 105600 | HM3: =-(HL$3+HL$30)/HL$30 -> -0.34237565 | HO3: Venda de café | HP3: =((HP$4*60)/0.25)*HP$5 -> 105600 | HQ3: =-(HP$3+HP$30)/HP$30 -> 0.84363993 | HS3: Venda de café | HT3: =((HT$4*60)/0.25)*HT$5 -> 105600 | HU3: =-(HT$3+HT$30)/HT$30 -> 0.84363993 | HW3: Venda de café | HX3: =((HX$4*60)/0.25)*HX$5 -> 105600 | HY3: =-(HX$3+HX$30)/HX$30 -> -0.34237565 | IA3: Venda de café | IB3: =((IB$4*60)/0.25)*IB$5 -> 105600 | IC3: =-(IB$3+IB$30)/IB$30 -> 0.84363993 | IE3: Venda de café | IF3: =((IF$4*60)/0.25)*IF$5 -> 105600 | IG3: =-(IF$3+IF$30)/IF$30 -> 0.84363993 | II3: Venda de café | IJ3: =((IJ$4*60)/0.25)*IJ$5 -> 115200 | IK3: =-(IJ$3+IJ$30)/IJ$30 -> -0.33824972 | IM3: Venda de café | IN3: =((IN$4*60)/0.25)*IN$5 -> 115200 | IO3: =-(IN$3+IN$30)/IN$30 -> 0.87366441 | IQ3: Venda de café | IR3: =((IR$4*60)/0.25)*IR$5 -> 115200 | IS3: =-(IR$3+IR$30)/IR$30 -> 0.87366441 | IU3: Venda de café | IV3: =((IV$4*60)/0.25)*IV$5 -> 115200 | IW3: =-(IV$3+IV$30)/IV$30 -> -0.33824972 | IY3: Venda de café | IZ3: =((IZ$4*60)/0.25)*IZ$5 -> 115200 | JA3: =-(IZ$3+IZ$30)/IZ$30 -> 0.87366441 | JC3: Venda de café | JD3: =((JD$4*60)/0.25)*JD$5 -> 115200 | JE3: =-(JD$3+JD$30)/JD$30 -> 0.87366441 | JG3: Venda de café | JH3: =((JH$4*60)/0.25)*JH$5 -> 115200 | JI3: =-(JH$3+JH$30)/JH$30 -> -0.36100746 | JK3: Venda de café | JL3: =((JL$4*60)/0.25)*JL$5 -> 124800 | JM3: =-(JL$3+JL$30)/JL$30 -> 0.89984424 | JO3: Venda de café | JP3: =((JP$4*60)/0.25)*JP$5 -> 124800 | JQ3: =-(JP$3+JP$30)/JP$30 -> 0.89984424 | JS3: Venda de café | JT3: =((JT$4*60)/0.25)*JT$5 -> 124800 | JU3: =-(JT$3+JT$30)/JT$30 -> -0.3347179 | JW3: Venda de café | JX3: =((JX$4*60)/0.25)*JX$5 -> 124800 | JY3: =-(JX$3+JX$30)/JX$30 -> 0.89984424 | KA3: Venda de café | KB3: =((KB$4*60)/0.25)*KB$5 -> 124800 | KC3: =-(KB$3+KB$30)/KB$30 -> 0.89984424 | KE3: Venda de café | KF3: =((KF$4*60)/0.25)*KF$5 -> 124800 | KG3: =-(KF$3+KF$30)/KF$30 -> 0.16646856
A4: 0.15 | C4: Sacas vendidas | D4: 3 | G4: Sacas vendidas | H4: =INT(3 + (COLUMN()-COLUMN($D4))/4 * $A$4) -> 3 | K4: Sacas vendidas | L4: =INT(3 + (COLUMN()-COLUMN($D4))/4 * $A$4) -> 3 | O4: Sacas vendidas | P4: =INT(3 + (COLUMN()-COLUMN($D4))/4 * $A$4) -> 3 | S4: Sacas vendidas | T4: =INT(3 + (COLUMN()-COLUMN($D4))/4 * $A$4) -> 3 | W4: Sacas vendidas | X4: =INT(3 + (COLUMN()-COLUMN($D4))/4 * $A$4) -> 3 | AA4: Sacas vendidas | AB4: =INT(3 + (COLUMN()-COLUMN($D4))/4 * $A$4) -> 3 | AE4: Sacas vendidas | AF4: =INT(3 + (COLUMN()-COLUMN($D4))/4 * $A$4) -> 4 | AI4: Sacas vendidas | AJ4: =INT(3 + (COLUMN()-COLUMN($D4))/4 * $A$4) -> 4 | AM4: Sacas vendidas | AN4: =INT(3 + (COLUMN()-COLUMN($D4))/4 * $A$4) -> 4 | AQ4: Sacas vendidas | AR4: =INT(3 + (COLUMN()-COLUMN($D4))/4 * $A$4) -> 4 | AU4: Sacas vendidas | AV4: =INT(3 + (COLUMN()-COLUMN($D4))/4 * $A$4) -> 4 | AY4: Sacas vendidas | AZ4: =INT(3 + (COLUMN()-COLUMN($D4))/4 * $A$4) -> 4 | BC4: Sacas vendidas | BD4: =INT(3 + (COLUMN()-COLUMN($D4))/4 * $A$4) -> 4 | BG4: Sacas vendidas | BH4: =INT(3 + (COLUMN()-COLUMN($D4))/4 * $A$4) -> 5 | BK4: Sacas vendidas | BL4: =INT(3 + (COLUMN()-COLUMN($D4))/4 * $A$4) -> 5 | BO4: Sacas vendidas | BP4: =INT(3 + (COLUMN()-COLUMN($D4))/4 * $A$4) -> 5 | BS4: Sacas vendidas | BT4: =INT(3 + (COLUMN()-COLUMN($D4))/4 * $A$4) -> 5 | BW4: Sacas vendidas | BX4: =INT(3 + (COLUMN()-COLUMN($D4))/4 * $A$4) -> 5 | CA4: Sacas vendidas | CB4: =INT(3 + (COLUMN()-COLUMN($D4))/4 * $A$4) -> 5 | CE4: Sacas vendidas | CF4: =INT(3 + (COLUMN()-COLUMN($D4))/4 * $A$4) -> 6 | CI4: Sacas vendidas | CJ4: =INT(3 + (COLUMN()-COLUMN($D4))/4 * $A$4) -> 6 | CM4: Sacas vendidas | CN4: =INT(3 + (COLUMN()-COLUMN($D4))/4 * $A$4) -> 6 | CQ4: Sacas vendidas | CR4: =INT(3 + (COLUMN()-COLUMN($D4))/4 * $A$4) -> 6 | CU4: Sacas vendidas | CV4: =INT(3 + (COLUMN()-COLUMN($D4))/4 * $A$4) -> 6 | CY4: Sacas vendidas | CZ4: =INT(3 + (COLUMN()-COLUMN($D4))/4 * $A$4) -> 6 | DC4: Sacas vendidas | DD4: =INT(3 + (COLUMN()-COLUMN($D4))/4 * $A$4) -> 6 | DG4: Sacas vendidas | DH4: =INT(3 + (COLUMN()-COLUMN($D4))/4 * $A$4) -> 7 | DK4: Sacas vendidas | DL4: =INT(3 + (COLUMN()-COLUMN($D4))/4 * $A$4) -> 7 | DO4: Sacas vendidas | DP4: =INT(3 + (COLUMN()-COLUMN($D4))/4 * $A$4) -> 7 | DS4: Sacas vendidas | DT4: =INT(3 + (COLUMN()-COLUMN($D4))/4 * $A$4) -> 7 | DW4: Sacas vendidas | DX4: =INT(3 + (COLUMN()-COLUMN($D4))/4 * $A$4) -> 7 | EA4: Sacas vendidas | EB4: =INT(3 + (COLUMN()-COLUMN($D4))/4 * $A$4) -> 7 | EE4: Sacas vendidas | EF4: =INT(3 + (COLUMN()-COLUMN($D4))/4 * $A$4) -> 7 | EI4: Sacas vendidas | EJ4: =INT(3 + (COLUMN()-COLUMN($D4))/4 * $A$4) -> 8 | EM4: Sacas vendidas | EN4: =INT(3 + (COLUMN()-COLUMN($D4))/4 * $A$4) -> 8 | EQ4: Sacas vendidas | ER4: =INT(3 + (COLUMN()-COLUMN($D4))/4 * $A$4) -> 8 | EU4: Sacas vendidas | EV4: =INT(3 + (COLUMN()-COLUMN($D4))/4 * $A$4) -> 8 | EY4: Sacas vendidas | EZ4: =INT(3 + (COLUMN()-COLUMN($D4))/4 * $A$4) -> 8 | FC4: Sacas vendidas | FD4: =INT(3 + (COLUMN()-COLUMN($D4))/4 * $A$4) -> 8 | FG4: Sacas vendidas | FH4: =INT(3 + (COLUMN()-COLUMN($D4))/4 * $A$4) -> 9 | FK4: Sacas vendidas | FL4: =INT(3 + (COLUMN()-COLUMN($D4))/4 * $A$4) -> 9 | FO4: Sacas vendidas | FP4: =INT(3 + (COLUMN()-COLUMN($D4))/4 * $A$4) -> 9 | FS4: Sacas vendidas | FT4: =INT(3 + (COLUMN()-COLUMN($D4))/4 * $A$4) -> 9 | FW4: Sacas vendidas | FX4: =INT(3 + (COLUMN()-COLUMN($D4))/4 * $A$4) -> 9 | GA4: Sacas vendidas | GB4: =INT(3 + (COLUMN()-COLUMN($D4))/4 * $A$4) -> 9 | GE4: Sacas vendidas | GF4: =INT(3 + (COLUMN()-COLUMN($D4))/4 * $A$4) -> 9 | GI4: Sacas vendidas | GJ4: =INT(3 + (COLUMN()-COLUMN($D4))/4 * $A$4) -> 10 | GM4: Sacas vendidas | GN4: =INT(3 + (COLUMN()-COLUMN($D4))/4 * $A$4) -> 10 | GQ4: Sacas vendidas | GR4: =INT(3 + (COLUMN()-COLUMN($D4))/4 * $A$4) -> 10 | GU4: Sacas vendidas | GV4: =INT(3 + (COLUMN()-COLUMN($D4))/4 * $A$4) -> 10 | GY4: Sacas vendidas | GZ4: =INT(3 + (COLUMN()-COLUMN($D4))/4 * $A$4) -> 10 | HC4: Sacas vendidas | HD4: =INT(3 + (COLUMN()-COLUMN($D4))/4 * $A$4) -> 10 | HG4: Sacas vendidas | HH4: =INT(3 + (COLUMN()-COLUMN($D4))/4 * $A$4) -> 10 | HK4: Sacas vendidas | HL4: =INT(3 + (COLUMN()-COLUMN($D4))/4 * $A$4) -> 11 | HO4: Sacas vendidas | HP4: =INT(3 + (COLUMN()-COLUMN($D4))/4 * $A$4) -> 11 | HS4: Sacas vendidas | HT4: =INT(3 + (COLUMN()-COLUMN($D4))/4 * $A$4) -> 11 | HW4: Sacas vendidas | HX4: =INT(3 + (COLUMN()-COLUMN($D4))/4 * $A$4) -> 11 | IA4: Sacas vendidas | IB4: =INT(3 + (COLUMN()-COLUMN($D4))/4 * $A$4) -> 11 | IE4: Sacas vendidas | IF4: =INT(3 + (COLUMN()-COLUMN($D4))/4 * $A$4) -> 11 | II4: Sacas vendidas | IJ4: =INT(3 + (COLUMN()-COLUMN($D4))/4 * $A$4) -> 12 | IM4: Sacas vendidas | IN4: =INT(3 + (COLUMN()-COLUMN($D4))/4 * $A$4) -> 12 | IQ4: Sacas vendidas | IR4: =INT(3 + (COLUMN()-COLUMN($D4))/4 * $A$4) -> 12 | IU4: Sacas vendidas | IV4: =INT(3 + (COLUMN()-COLUMN($D4))/4 * $A$4) -> 12 | IY4: Sacas vendidas | IZ4: =INT(3 + (COLUMN()-COLUMN($D4))/4 * $A$4) -> 12 | JC4: Sacas vendidas | JD4: =INT(3 + (COLUMN()-COLUMN($D4))/4 * $A$4) -> 12 | JG4: Sacas vendidas | JH4: =INT(3 + (COLUMN()-COLUMN($D4))/4 * $A$4) -> 12 | JK4: Sacas vendidas | JL4: =INT(3 + (COLUMN()-COLUMN($D4))/4 * $A$4) -> 13 | JO4: Sacas vendidas | JP4: =INT(3 + (COLUMN()-COLUMN($D4))/4 * $A$4) -> 13 | JS4: Sacas vendidas | JT4: =INT(3 + (COLUMN()-COLUMN($D4))/4 * $A$4) -> 13 | JW4: Sacas vendidas | JX4: =INT(3 + (COLUMN()-COLUMN($D4))/4 * $A$4) -> 13 | KA4: Sacas vendidas | KB4: =INT(3 + (COLUMN()-COLUMN($D4))/4 * $A$4) -> 13 | KE4: Sacas vendidas | KF4: =INT(3 + (COLUMN()-COLUMN($D4))/4 * $A$4) -> 13
C5: Preço por pacotinho | D5: =$A$3 -> 40 | G5: Preço por pacotinho | H5: =$A$3 -> 40 | K5: Preço por pacotinho | L5: =$A$3 -> 40 | O5: Preço por pacotinho | P5: =$A$3 -> 40 | S5: Preço por pacotinho | T5: =$A$3 -> 40 | W5: Preço por pacotinho | X5: =$A$3 -> 40 | AA5: Preço por pacotinho | AB5: =$A$3 -> 40 | AE5: Preço por pacotinho | AF5: =$A$3 -> 40 | AI5: Preço por pacotinho | AJ5: =$A$3 -> 40 | AM5: Preço por pacotinho | AN5: =$A$3 -> 40 | AQ5: Preço por pacotinho | AR5: =$A$3 -> 40 | AU5: Preço por pacotinho | AV5: =$A$3 -> 40 | AY5: Preço por pacotinho | AZ5: =$A$3 -> 40 | BC5: Preço por pacotinho | BD5: =$A$3 -> 40 | BG5: Preço por pacotinho | BH5: =$A$3 -> 40 | BK5: Preço por pacotinho | BL5: =$A$3 -> 40 | BO5: Preço por pacotinho | BP5: =$A$3 -> 40 | BS5: Preço por pacotinho | BT5: =$A$3 -> 40 | BW5: Preço por pacotinho | BX5: =$A$3 -> 40 | CA5: Preço por pacotinho | CB5: =$A$3 -> 40 | CE5: Preço por pacotinho | CF5: =$A$3 -> 40 | CI5: Preço por pacotinho | CJ5: =$A$3 -> 40 | CM5: Preço por pacotinho | CN5: =$A$3 -> 40 | CQ5: Preço por pacotinho | CR5: =$A$3 -> 40 | CU5: Preço por pacotinho | CV5: =$A$3 -> 40 | CY5: Preço por pacotinho | CZ5: =$A$3 -> 40 | DC5: Preço por pacotinho | DD5: =$A$3 -> 40 | DG5: Preço por pacotinho | DH5: =$A$3 -> 40 | DK5: Preço por pacotinho | DL5: =$A$3 -> 40 | DO5: Preço por pacotinho | DP5: =$A$3 -> 40 | DS5: Preço por pacotinho | DT5: =$A$3 -> 40 | DW5: Preço por pacotinho | DX5: =$A$3 -> 40 | EA5: Preço por pacotinho | EB5: =$A$3 -> 40 | EE5: Preço por pacotinho | EF5: =$A$3 -> 40 | EI5: Preço por pacotinho | EJ5: =$A$3 -> 40 | EM5: Preço por pacotinho | EN5: =$A$3 -> 40 | EQ5: Preço por pacotinho | ER5: =$A$3 -> 40 | EU5: Preço por pacotinho | EV5: =$A$3 -> 40 | EY5: Preço por pacotinho | EZ5: =$A$3 -> 40 | FC5: Preço por pacotinho | FD5: =$A$3 -> 40 | FG5: Preço por pacotinho | FH5: =$A$3 -> 40 | FK5: Preço por pacotinho | FL5: =$A$3 -> 40 | FO5: Preço por pacotinho | FP5: =$A$3 -> 40 | FS5: Preço por pacotinho | FT5: =$A$3 -> 40 | FW5: Preço por pacotinho | FX5: =$A$3 -> 40 | GA5: Preço por pacotinho | GB5: =$A$3 -> 40 | GE5: Preço por pacotinho | GF5: =$A$3 -> 40 | GI5: Preço por pacotinho | GJ5: =$A$3 -> 40 | GM5: Preço por pacotinho | GN5: =$A$3 -> 40 | GQ5: Preço por pacotinho | GR5: =$A$3 -> 40 | GU5: Preço por pacotinho | GV5: =$A$3 -> 40 | GY5: Preço por pacotinho | GZ5: =$A$3 -> 40 | HC5: Preço por pacotinho | HD5: =$A$3 -> 40 | HG5: Preço por pacotinho | HH5: =$A$3 -> 40 | HK5: Preço por pacotinho | HL5: =$A$3 -> 40 | HO5: Preço por pacotinho | HP5: =$A$3 -> 40 | HS5: Preço por pacotinho | HT5: =$A$3 -> 40 | HW5: Preço por pacotinho | HX5: =$A$3 -> 40 | IA5: Preço por pacotinho | IB5: =$A$3 -> 40 | IE5: Preço por pacotinho | IF5: =$A$3 -> 40 | II5: Preço por pacotinho | IJ5: =$A$3 -> 40 | IM5: Preço por pacotinho | IN5: =$A$3 -> 40 | IQ5: Preço por pacotinho | IR5: =$A$3 -> 40 | IU5: Preço por pacotinho | IV5: =$A$3 -> 40 | IY5: Preço por pacotinho | IZ5: =$A$3 -> 40 | JC5: Preço por pacotinho | JD5: =$A$3 -> 40 | JG5: Preço por pacotinho | JH5: =$A$3 -> 40 | JK5: Preço por pacotinho | JL5: =$A$3 -> 40 | JO5: Preço por pacotinho | JP5: =$A$3 -> 40 | JS5: Preço por pacotinho | JT5: =$A$3 -> 40 | JW5: Preço por pacotinho | JX5: =$A$3 -> 40 | KA5: Preço por pacotinho | KB5: =$A$3 -> 40 | KE5: Preço por pacotinho | KF5: =$A$3 -> 40
C7: Total receitas | D7: =SUM(D$3) -> 28800 | G7: Total receitas | H7: =SUM(H$3) -> 28800 | K7: Total receitas | L7: =SUM(L$3) -> 28800 | O7: Total receitas | P7: =SUM(P$3) -> 28800 | S7: Total receitas | T7: =SUM(T$3) -> 28800 | W7: Total receitas | X7: =SUM(X$3) -> 28800 | AA7: Total receitas | AB7: =SUM(AB$3) -> 28800 | AE7: Total receitas | AF7: =SUM(AF$3) -> 38400 | AI7: Total receitas | AJ7: =SUM(AJ$3) -> 38400 | AM7: Total receitas | AN7: =SUM(AN$3) -> 38400 | AQ7: Total receitas | AR7: =SUM(AR$3) -> 38400 | AU7: Total receitas | AV7: =SUM(AV$3) -> 38400 | AY7: Total receitas | AZ7: =SUM(AZ$3) -> 38400 | BC7: Total receitas | BD7: =SUM(BD$3) -> 38400 | BG7: Total receitas | BH7: =SUM(BH$3) -> 48000 | BK7: Total receitas | BL7: =SUM(BL$3) -> 48000 | BO7: Total receitas | BP7: =SUM(BP$3) -> 48000 | BS7: Total receitas | BT7: =SUM(BT$3) -> 48000 | BW7: Total receitas | BX7: =SUM(BX$3) -> 48000 | CA7: Total receitas | CB7: =SUM(CB$3) -> 48000 | CE7: Total receitas | CF7: =SUM(CF$3) -> 57600 | CI7: Total receitas | CJ7: =SUM(CJ$3) -> 57600 | CM7: Total receitas | CN7: =SUM(CN$3) -> 57600 | CQ7: Total receitas | CR7: =SUM(CR$3) -> 57600 | CU7: Total receitas | CV7: =SUM(CV$3) -> 57600 | CY7: Total receitas | CZ7: =SUM(CZ$3) -> 57600 | DC7: Total receitas | DD7: =SUM(DD$3) -> 57600 | DG7: Total receitas | DH7: =SUM(DH$3) -> 67200 | DK7: Total receitas | DL7: =SUM(DL$3) -> 67200 | DO7: Total receitas | DP7: =SUM(DP$3) -> 67200 | DS7: Total receitas | DT7: =SUM(DT$3) -> 67200 | DW7: Total receitas | DX7: =SUM(DX$3) -> 67200 | EA7: Total receitas | EB7: =SUM(EB$3) -> 67200 | EE7: Total receitas | EF7: =SUM(EF$3) -> 67200 | EI7: Total receitas | EJ7: =SUM(EJ$3) -> 76800 | EM7: Total receitas | EN7: =SUM(EN$3) -> 76800 | EQ7: Total receitas | ER7: =SUM(ER$3) -> 76800 | EU7: Total receitas | EV7: =SUM(EV$3) -> 76800 | EY7: Total receitas | EZ7: =SUM(EZ$3) -> 76800 | FC7: Total receitas | FD7: =SUM(FD$3) -> 76800 | FG7: Total receitas | FH7: =SUM(FH$3) -> 86400 | FK7: Total receitas | FL7: =SUM(FL$3) -> 86400 | FO7: Total receitas | FP7: =SUM(FP$3) -> 86400 | FS7: Total receitas | FT7: =SUM(FT$3) -> 86400 | FW7: Total receitas | FX7: =SUM(FX$3) -> 86400 | GA7: Total receitas | GB7: =SUM(GB$3) -> 86400 | GE7: Total receitas | GF7: =SUM(GF$3) -> 86400 | GI7: Total receitas | GJ7: =SUM(GJ$3) -> 96000 | GM7: Total receitas | GN7: =SUM(GN$3) -> 96000 | GQ7: Total receitas | GR7: =SUM(GR$3) -> 96000 | GU7: Total receitas | GV7: =SUM(GV$3) -> 96000 | GY7: Total receitas | GZ7: =SUM(GZ$3) -> 96000 | HC7: Total receitas | HD7: =SUM(HD$3) -> 96000 | HG7: Total receitas | HH7: =SUM(HH$3) -> 96000 | HK7: Total receitas | HL7: =SUM(HL$3) -> 105600 | HO7: Total receitas | HP7: =SUM(HP$3) -> 105600 | HS7: Total receitas | HT7: =SUM(HT$3) -> 105600 | HW7: Total receitas | HX7: =SUM(HX$3) -> 105600 | IA7: Total receitas | IB7: =SUM(IB$3) -> 105600 | IE7: Total receitas | IF7: =SUM(IF$3) -> 105600 | II7: Total receitas | IJ7: =SUM(IJ$3) -> 115200 | IM7: Total receitas | IN7: =SUM(IN$3) -> 115200 | IQ7: Total receitas | IR7: =SUM(IR$3) -> 115200 | IU7: Total receitas | IV7: =SUM(IV$3) -> 115200 | IY7: Total receitas | IZ7: =SUM(IZ$3) -> 115200 | JC7: Total receitas | JD7: =SUM(JD$3) -> 115200 | JG7: Total receitas | JH7: =SUM(JH$3) -> 115200 | JK7: Total receitas | JL7: =SUM(JL$3) -> 124800 | JO7: Total receitas | JP7: =SUM(JP$3) -> 124800 | JS7: Total receitas | JT7: =SUM(JT$3) -> 124800 | JW7: Total receitas | JX7: =SUM(JX$3) -> 124800 | KA7: Total receitas | KB7: =SUM(KB$3) -> 124800 | KE7: Total receitas | KF7: =SUM(KF$3) -> 124800
C9: Despesas | D9: R$ | G9: Despesas | H9: R$ | K9: Despesas | L9: R$ | O9: Despesas | P9: R$ | S9: Despesas | T9: R$ | W9: Despesas | X9: R$ | AA9: Despesas | AB9: R$ | AE9: Despesas | AF9: R$ | AI9: Despesas | AJ9: R$ | AM9: Despesas | AN9: R$ | AQ9: Despesas | AR9: R$ | AU9: Despesas | AV9: R$ | AY9: Despesas | AZ9: R$ | BC9: Despesas | BD9: R$ | BG9: Despesas | BH9: R$ | BK9: Despesas | BL9: R$ | BO9: Despesas | BP9: R$ | BS9: Despesas | BT9: R$ | BW9: Despesas | BX9: R$ | CA9: Despesas | CB9: R$ | CE9: Despesas | CF9: R$ | CI9: Despesas | CJ9: R$ | CM9: Despesas | CN9: R$ | CQ9: Despesas | CR9: R$ | CU9: Despesas | CV9: R$ | CY9: Despesas | CZ9: R$ | DC9: Despesas | DD9: R$ | DG9: Despesas | DH9: R$ | DK9: Despesas | DL9: R$ | DO9: Despesas | DP9: R$ | DS9: Despesas | DT9: R$ | DW9: Despesas | DX9: R$ | EA9: Despesas | EB9: R$ | EE9: Despesas | EF9: R$ | EI9: Despesas | EJ9: R$ | EM9: Despesas | EN9: R$ | EQ9: Despesas | ER9: R$ | EU9: Despesas | EV9: R$ | EY9: Despesas | EZ9: R$ | FC9: Despesas | FD9: R$ | FG9: Despesas | FH9: R$ | FK9: Despesas | FL9: R$ | FO9: Despesas | FP9: R$ | FS9: Despesas | FT9: R$ | FW9: Despesas | FX9: R$ | GA9: Despesas | GB9: R$ | GE9: Despesas | GF9: R$ | GI9: Despesas | GJ9: R$ | GM9: Despesas | GN9: R$ | GQ9: Despesas | GR9: R$ | GU9: Despesas | GV9: R$ | GY9: Despesas | GZ9: R$ | HC9: Despesas | HD9: R$ | HG9: Despesas | HH9: R$ | HK9: Despesas | HL9: R$ | HO9: Despesas | HP9: R$ | HS9: Despesas | HT9: R$ | HW9: Despesas | HX9: R$ | IA9: Despesas | IB9: R$ | IE9: Despesas | IF9: R$ | II9: Despesas | IJ9: R$ | IM9: Despesas | IN9: R$ | IQ9: Despesas | IR9: R$ | IU9: Despesas | IV9: R$ | IY9: Despesas | IZ9: R$ | JC9: Despesas | JD9: R$ | JG9: Despesas | JH9: R$ | JK9: Despesas | JL9: R$ | JO9: Despesas | JP9: R$ | JS9: Despesas | JT9: R$ | JW9: Despesas | JX9: R$ | KA9: Despesas | KB9: R$ | KE9: Despesas | KF9: R$
A10: Despesas iniciais | C10: Máquina de torra seminova | D10: =-'Investimento Inicial'!$B$2 -> -70000
A11: Despesas fixas | C11: Balança de comércio | D11: =-'Investimento Inicial'!$B$3 -> -500
